<mujoco model="cable_trunk_model_example">
  <compiler angle="radian"/>

  <extension>
    <plugin plugin="mujoco.elasticity.cable"/>
  </extension>

  <custom>
    <text name="composite_actuated" data="rope_actuated"/>
  </custom>

  <asset>
    <texture type="2d" name="grid" builtin="checker" rgb1="0.1 0.2 0.3" rgb2="0.2 0.3 0.4" width="300" height="300"/>
    <material name="grid" texture="grid" texrepeat="8 8" reflectance="0.2"/>
  </asset>

  <worldbody>
    <camera name="yz_view" pos="0 -1.3 0.35" xyaxes="1 0 0 0 0 1"/>
    <geom size="10 10 0.01" type="plane" material="grid"/>
    <light pos="0 0 2" dir="0 0 -1"/>
    <body name="actuatedB_first" pos="0 0 0.7" quat="0 -0.707107 0 0.707107">
      <joint name="actuatedJ_0" pos="0 0 0" type="hinge" axis="0 1 0" group="3" stiffness="0.9" actuatorfrclimited="false" damping="0.044"/>
      <geom name="actuatedG0" size="0.005 0.0625" pos="0.0625 0 0" quat="0.707107 0 -0.707107 0" type="capsule" rgba="0.8 0.2 0.1 1"/>
      <site name="actuatedS_first" pos="0 0 0" group="3"/>
      <body name="actuatedB_1" pos="0.125 0 0">
        <joint name="actuatedJ_1" pos="0 0 0" type="hinge" axis="0 1 0" group="3" stiffness="0.9" actuatorfrclimited="false" damping="0.044"/>
        <geom name="actuatedG1" size="0.005 0.0625" pos="0.0625 0 0" quat="0.707107 0 -0.707107 0" type="capsule" rgba="0.8 0.2 0.1 1"/>
        <body name="actuatedB_2" pos="0.125 0 0">
          <joint name="actuatedJ_2" pos="0 0 0" type="hinge" axis="0 1 0" group="3" stiffness="0.9" actuatorfrclimited="false" damping="0.044"/>
          <geom name="actuatedG2" size="0.005 0.0625" pos="0.0625 0 0" quat="0.707107 0 -0.707107 0" type="capsule" rgba="0.8 0.2 0.1 1"/>
          <body name="actuatedB_last" pos="0.125 0 0">
            <joint name="actuatedJ_3" pos="0 0 0" type="hinge" axis="0 1 0" group="3" stiffness="0.9" actuatorfrclimited="false" damping="0.044"/>
            <geom name="actuatedG3" size="0.005 0.0625" pos="0.0625 0 0" quat="0.707107 0 -0.707107 0" type="capsule" rgba="0.8 0.2 0.1 1"/>
            <site name="actuatedS_last" pos="0.125 0 0" group="3"/>
            <site name="endeffector" pos="0.125 0 0"/> 
          </body>
        </body>
      </body>
    </body>
  </worldbody>

   <actuator>
    <motor name="actuator_0" joint="actuatedJ_0" gear="2"/>
    <motor name="actuator_1" joint="actuatedJ_1" gear="2"/>
    <motor name="actuator_2" joint="actuatedJ_2" gear="2"/>
    <motor name="actuator_3" joint="actuatedJ_3" gear="2"/>
  </actuator>

  <contact>
    <exclude body1="actuatedB_first" body2="actuatedB_1"/>
    <exclude body1="actuatedB_1" body2="actuatedB_2"/>
    <exclude body1="actuatedB_2" body2="actuatedB_last"/>
  </contact>

  <visual>
  <global offwidth="1920" offheight="1080"/>
  </visual>
  
</mujoco>
